<?xml version="1.0" ?>
<!-- Real turtle robot from Onshape export, adapted for MJPC Turtle 3D Swimming task.
     Actuators replaced with velocity type; MJPC sites added to root body. -->
<mujoco model="turtle_3dswimming_body">
  <compiler angle="radian" meshdir="assets" autolimits="true"/>
  <option integrator="implicit" timestep="0.005" gravity="0 0 0" density="1000" viscosity="0.0009" cone="elliptic" noslip_iterations="1"/>
  <default>
    <default class="turtle">
      <default class="visual">
        <geom type="mesh" contype="0" conaffinity="0" group="2"/>
      </default>
      <default class="collision">
        <geom group="3"/>
      </default>
    </default>
    <default class="fluid-ellipsoid-model">
        <geom fluidshape="ellipsoid"/>
    </default>
  </default>
  <worldbody>
    <!-- Link fr13_s105k (root body — free base) -->
    <body name="fr13_s105k" pos="0 0 0" quat="1 0 0 0" childclass="turtle">
      <inertial pos="-0.196495 0.00135248 0.0717682" mass="6.33343" fullinertia="0.137185 0.0361035 0.148315 0.000586929 -4.92463e-05 -0.00482738"/>
      <joint name="world_frame_to_base" type="free" axis="0.0 -1.0 0.0" />

      <!-- MJPC task sites: body-frame positions for head (front), tail (rear), and CoM -->
      <!-- Convention: -y = forward/head direction, +y = rear/tail direction -->
      <site name="base_cog"  pos="-0.196495  0.00135248 0.0717682"/>
      <site name="head_pos"  pos="-0.196    -0.22       0.072"/>
      <site name="tail_pos"  pos="-0.196     0.28       0.072"/>

      <!-- Part shell_bottom_bl -->
      <geom type="mesh" class="visual" pos="-0.193066 0.0607691 0.0949323" quat="0.706451 0.03038 0.0331563 -0.706332" mesh="shell_bottom_bl" material="shell_bottom_bl_material"/>
      <geom type="mesh" class="collision" pos="-0.193066 0.0607691 0.0949323" quat="0.706451 0.03038 0.0331563 -0.706332" mesh="shell_bottom_bl" material="shell_bottom_bl_material"/>
      <!-- Part shell -->
      <geom type="mesh" class="visual" pos="-0.193066 0.0607691 0.0949323" quat="0.706451 0.03038 0.0331563 -0.706332" mesh="shell" material="shell_material"/>
      <geom type="mesh" class="collision" pos="-0.193066 0.0607691 0.0949323" quat="0.706451 0.03038 0.0331563 -0.706332" mesh="shell" material="shell_material"/>
      <!-- Part protector -->
      <geom type="mesh" class="visual" pos="-0.0607344 -0.104872 0.0406092" quat="0.707107 0.707107 0.000629741 0.000629741" mesh="protector" material="protector_material"/>
      <geom type="mesh" class="collision" pos="-0.0607344 -0.104872 0.0406092" quat="0.707107 0.707107 0.000629741 0.000629741" mesh="protector" material="protector_material"/>
      <!-- Part 4in_tube -->
      <geom type="mesh" class="visual" pos="-0.196045 -0.0992129 0.0731481" quat="7.88867e-16 -0.707736 0.706477 -5.03839e-16" mesh="4in_tube" material="4in_tube_material"/>
      <!-- Part shell_2 -->
      <geom type="mesh" class="visual" pos="-0.193066 0.0607691 0.0949323" quat="0.706451 0.03038 0.0331563 -0.706332" mesh="shell__2" material="shell__2_material"/>
      <geom type="mesh" class="collision" pos="-0.193066 0.0607691 0.0949323" quat="0.706451 0.03038 0.0331563 -0.706332" mesh="shell__2" material="shell__2_material"/>
      <!-- Part shell_bottom_br -->
      <geom type="mesh" class="visual" pos="-0.193066 0.0607691 0.0949323" quat="0.706451 0.03038 0.0331563 -0.706332" mesh="shell_bottom_br" material="shell_bottom_br_material"/>
      <geom type="mesh" class="collision" pos="-0.193066 0.0607691 0.0949323" quat="0.706451 0.03038 0.0331563 -0.706332" mesh="shell_bottom_br" material="shell_bottom_br_material"/>
      <!-- Part shell_bottom_fl -->
      <geom type="mesh" class="visual" pos="-0.193066 0.0607691 0.0949323" quat="0.706451 0.03038 0.0331563 -0.706332" mesh="shell_bottom_fl" material="shell_bottom_fl_material"/>
      <geom type="mesh" class="collision" pos="-0.193066 0.0607691 0.0949323" quat="0.706451 0.03038 0.0331563 -0.706332" mesh="shell_bottom_fl" material="shell_bottom_fl_material"/>
      <!-- Part explorehd camera (no collision) -->
      <geom type="mesh" class="visual" pos="-0.171515 -0.255003 0.0888314" quat="0.70089 0.70089 0.0935589 0.0935589" mesh="explorehd_2_0_public_step_1_solid1" material="explorehd_2_0_public_step_1_solid1_material"/>
      <!-- Part shell_bottom_bm -->
      <geom type="mesh" class="visual" pos="-0.193066 0.0607691 0.0949323" quat="0.706451 0.03038 0.0331563 -0.706332" mesh="shell_bottom_bm" material="shell_bottom_bm_material"/>
      <geom type="mesh" class="collision" pos="-0.193066 0.0607691 0.0949323" quat="0.706451 0.03038 0.0331563 -0.706332" mesh="shell_bottom_bm" material="shell_bottom_bm_material"/>
      <!-- Part fr13_s105k body (visual only) -->
      <geom type="mesh" class="visual" pos="-0.111735 -0.104563 0.0406092" quat="0.500445 0.499555 0.500445 -0.499555" mesh="fr13_s105k" material="fr13_s105k_material"/>
      <!-- Part wte4_m_clamp -->
      <geom type="mesh" class="visual" pos="-0.195579 -0.079712 0.0731481" quat="0.500445 0.499555 0.500445 -0.499555" mesh="wte4_m_clamp" material="wte4_m_clamp_material"/>
      <!-- Part 4in_flange (front) -->
      <geom type="mesh" class="visual" pos="-0.196082 -0.0782129 0.0731481" quat="0.707107 0.707107 0.000629741 0.000629741" mesh="4in_flange" material="4in_flange_material"/>
      <!-- Part head_bottom -->
      <geom type="mesh" class="visual" pos="-0.195957 -0.148475 0.0604314" quat="0.707106 0.707106 0.00127394 0.00127394" mesh="head_bottom" material="head_bottom_material"/>
      <geom type="mesh" class="collision" pos="-0.195957 -0.148475 0.0604314" quat="0.707106 0.707106 0.00127394 0.00127394" mesh="head_bottom" material="head_bottom_material"/>
      <!-- Part shell_3 -->
      <geom type="mesh" class="visual" pos="-0.193066 0.0607691 0.0949323" quat="0.706451 0.03038 0.0331563 -0.706332" mesh="shell__3" material="shell__3_material"/>
      <geom type="mesh" class="collision" pos="-0.193066 0.0607691 0.0949323" quat="0.706451 0.03038 0.0331563 -0.706332" mesh="shell__3" material="shell__3_material"/>
      <!-- Part 4in_flange (rear) -->
      <geom type="mesh" class="visual" pos="-0.196542 0.179787 0.0731481" quat="0.000629741 0.000629741 -0.707107 -0.707107" mesh="4in_flange" material="4in_flange_material"/>
      <!-- Part xw540 motor (front left mount) -->
      <geom type="mesh" class="visual" pos="-0.0607351 -0.104472 0.0406092" quat="0.500445 0.499555 0.500445 -0.499555" mesh="xw540_n105_i101_stp" material="xw540_n105_i101_stp_material"/>
      <geom type="mesh" class="collision" pos="-0.0607351 -0.104472 0.0406092" quat="0.500445 0.499555 0.500445 -0.499555" mesh="xw540_n105_i101_stp" material="xw540_n105_i101_stp_material"/>
      <!-- Part xw540 motor (front right mount) -->
      <geom type="mesh" class="visual" pos="-0.331335 -0.104954 0.0406092" quat="0.499555 0.500445 -0.499555 0.500445" mesh="xw540_n105_i101_stp" material="xw540_n105_i101_stp_material"/>
      <geom type="mesh" class="collision" pos="-0.331335 -0.104954 0.0406092" quat="0.499555 0.500445 -0.499555 0.500445" mesh="xw540_n105_i101_stp" material="xw540_n105_i101_stp_material"/>
      <!-- Part shell_bottom_fm -->
      <geom type="mesh" class="visual" pos="-0.193066 0.0607691 0.0949323" quat="0.706451 0.03038 0.0331563 -0.706332" mesh="shell_bottom_fm" material="shell_bottom_fm_material"/>
      <geom type="mesh" class="collision" pos="-0.193066 0.0607691 0.0949323" quat="0.706451 0.03038 0.0331563 -0.706332" mesh="shell_bottom_fm" material="shell_bottom_fm_material"/>
      <!-- Part explorehd camera 2 (no collision) -->
      <geom type="mesh" class="visual" pos="-0.219736 -0.25548 0.0888314" quat="0.701223 0.701223 -0.0910328 -0.0910328" mesh="explorehd_2_0_public_step_1_solid1" material="explorehd_2_0_public_step_1_solid1_material"/>
      <!-- Part fr13_h105k (visual, rear hub area) -->
      <geom type="mesh" class="visual" pos="-0.282684 0.203633 0.0406092" quat="0.500445 -0.499555 -0.500445 -0.499555" mesh="fr13_h105k" material="fr13_h105k_material"/>
      <!-- Part wte4_m_clamp_2 -->
      <geom type="mesh" class="visual" pos="-0.196579 -0.0797138 0.0731481" quat="0.499555 0.500445 -0.499555 0.500445" mesh="wte4_m_clamp" material="wte4_m_clamp_material"/>
      <!-- Part wte4_m_clamp_3 -->
      <geom type="mesh" class="visual" pos="-0.196044 0.181288 0.0731481" quat="0.500445 -0.499555 -0.500445 -0.499555" mesh="wte4_m_clamp" material="wte4_m_clamp_material"/>
      <!-- Part head_top -->
      <geom type="mesh" class="visual" pos="-0.195957 -0.148475 0.0604314" quat="0.707106 0.707106 0.00127394 0.00127394" mesh="head_top" material="head_top_material"/>
      <geom type="mesh" class="collision" pos="-0.195957 -0.148475 0.0604314" quat="0.707106 0.707106 0.00127394 0.00127394" mesh="head_top" material="head_top_material"/>
      <!-- Part fr13_s105k_2 (visual) -->
      <geom type="mesh" class="visual" pos="-0.280335 -0.104863 0.0406092" quat="0.499555 0.500445 -0.499555 0.500445" mesh="fr13_s105k" material="fr13_s105k_material"/>
      <!-- Part wte4_m_clamp_4 -->
      <geom type="mesh" class="visual" pos="-0.197044 0.181286 0.0731481" quat="0.499555 -0.500445 0.499555 0.500445" mesh="wte4_m_clamp" material="wte4_m_clamp_material"/>
      <!-- Part wte4_end_cap (front) -->
      <geom type="mesh" class="visual" pos="-0.196034 -0.105213 0.0731481" quat="0.000629741 -0.000629741 0.707107 -0.707107" mesh="wte4_end_cap_10xm10_r2" material="wte4_end_cap_10xm10_r2_material"/>
      <!-- Part wte4_end_cap (rear) -->
      <geom type="mesh" class="visual" pos="-0.19659 0.206787 0.0731481" quat="0.000629741 0.000629741 -0.707107 -0.707107" mesh="wte4_end_cap_10xm10_r2" material="wte4_end_cap_10xm10_r2_material"/>
      <!-- Part shell_4 -->
      <geom type="mesh" class="visual" pos="-0.193066 0.0607691 0.0949323" quat="0.706451 0.03038 0.0331563 -0.706332" mesh="shell__4" material="shell__4_material"/>
      <geom type="mesh" class="collision" pos="-0.193066 0.0607691 0.0949323" quat="0.706451 0.03038 0.0331563 -0.706332" mesh="shell__4" material="shell__4_material"/>
      <!-- Part shell_bottom_fr -->
      <geom type="mesh" class="visual" pos="-0.193066 0.0607691 0.0949323" quat="0.706451 0.03038 0.0331563 -0.706332" mesh="shell_bottom_fr" material="shell_bottom_fr_material"/>
      <geom type="mesh" class="collision" pos="-0.193066 0.0607691 0.0949323" quat="0.706451 0.03038 0.0331563 -0.706332" mesh="shell_bottom_fr" material="shell_bottom_fr_material"/>
      <!-- Part protector_2 -->
      <geom type="mesh" class="visual" pos="-0.331335 -0.104954 0.0406092" quat="0.707107 0.707107 0.000629741 0.000629741" mesh="protector" material="protector_material"/>
      <geom type="mesh" class="collision" pos="-0.331335 -0.104954 0.0406092" quat="0.707107 0.707107 0.000629741 0.000629741" mesh="protector" material="protector_material"/>

      <!-- ===================== LEFT FRONT FLIPPER CHAIN ===================== -->
      <body name="left_front_link_1" pos="-0.0607821 -0.0780719 0.0406092" quat="0.500445 0.499555 0.500445 -0.499555">
        <joint name="shoulderL1" type="hinge" axis="0 0 -1" range="-1.0 1.0"/>
        <inertial pos="-0.000940071 0.0536412 0.0112038" mass="0.245024" fullinertia="0.000128486 0.000131437 9.86795e-05 1.004e-06 -3.62127e-06 9.71519e-06"/>
        <geom type="mesh" class="visual" pos="6.245e-17 0.058 -0.0045" quat="0.5 -0.5 0.5 -0.5" mesh="xw540_n105_i101_stp" material="xw540_n105_i101_stp_material"/>
        <geom type="mesh" class="collision" pos="6.245e-17 0.058 -0.0045" quat="0.5 -0.5 0.5 -0.5" mesh="xw540_n105_i101_stp" material="xw540_n105_i101_stp_material"/>
        <geom type="mesh" class="visual" pos="0.0004 0.058 -0.0045" quat="0.5 0.5 0.5 0.5" mesh="protector" material="protector_material"/>
        <geom type="mesh" class="collision" pos="0.0004 0.058 -0.0045" quat="0.5 0.5 0.5 0.5" mesh="protector" material="protector_material"/>
        <geom type="mesh" class="visual" pos="2.08167e-17 0.032 0.011" quat="0.707107 6.62943e-16 0.707107 -3.92187e-16" mesh="fr13_s106k" material="fr13_s106k_material"/>
        <geom type="mesh" class="visual" pos="4.85723e-17 0.03 0.0265" quat="0.707107 -6.79418e-17 0.707107 -3.38828e-16" mesh="fr13_h105k" material="fr13_h105k_material"/>
        <body name="left_front_link_2" pos="0.0265 0.058 -0.0045" quat="0.5 0.5 -0.5 -0.5">
          <joint name="shoulderL2" type="hinge" range="-1.0 1.0"/>
          <inertial pos="0.00102508 -0.0165904 -0.0243109" mass="0.224704" fullinertia="9.36859e-05 7.47238e-05 0.000114792 3.31983e-06 3.89075e-07 -4.1386e-07"/>
          <geom type="mesh" class="visual" pos="1.04083e-17 -0.031 -0.026" quat="6.27293e-18 0.707107 -0 -0.707107" mesh="xw540_n105_i101_stp" material="xw540_n105_i101_stp_material"/>
          <geom type="mesh" class="collision" pos="1.04083e-17 -0.031 -0.026" quat="6.27293e-18 0.707107 -0 -0.707107" mesh="xw540_n105_i101_stp" material="xw540_n105_i101_stp_material"/>
          <geom type="mesh" class="visual" pos="6.07153e-18 -0.0155 1.73472e-18" quat="0.5 -0.5 0.5 -0.5" mesh="fr13_s106k" material="fr13_s106k_material"/>
          <geom type="mesh" class="visual" pos="-0.0004 -0.031 -0.026" quat="0.5 0.5 -0.5 -0.5" mesh="protector" material="protector_material"/>
          <geom type="mesh" class="collision" pos="-0.0004 -0.031 -0.026" quat="0.5 0.5 -0.5 -0.5" mesh="protector" material="protector_material"/>
          <body name="left_flipper" pos="-0.0265 -0.031 -0.026" quat="0.707107 -1.82586e-17 0.707107 -8.82852e-17">
            <joint name="shoulderL3" type="hinge" range="-1.3 1.3"/>
            <inertial pos="-9.56975e-09 -0.00507293 -0.139314" mass="0.254495" fullinertia="0.00108025 0.000995743 9.46776e-05 -1.47703e-10 5.8036e-10 -4.08156e-05"/>
            <geom type="mesh" class="visual" pos="1.31492e-15 -0.0224902 -0.147823" quat="0.40558 -0.579228 -0.40558 0.579228" mesh="flipper_silicone" material="flipper_silicone_material"/>
            <geom type="mesh" class="collision" fluidshape="ellipsoid" pos="1.31492e-15 -0.0224902 -0.147823" quat="0.40558 -0.579228 -0.40558 0.579228" mesh="flipper_silicone" material="flipper_silicone_material"/>
            <geom type="mesh" class="visual" pos="6.08888e-16 -0.0018751 -0.0539563" quat="0.477714 -0.521334 -0.477714 0.521334" mesh="joint_pin" material="joint_pin_material"/>
            <geom type="mesh" class="visual" pos="5.72459e-16 -0.0018751 -0.0539563" quat="0.477714 -0.521334 -0.477714 0.521334" mesh="joint_clamp" material="joint_clamp_material"/>
            <geom type="mesh" class="visual" pos="5.96745e-16 -0.0306545 -0.0482414" quat="0.420603 -0.568413 -0.420603 0.568413" mesh="joint_clamp" material="joint_clamp_material"/>
            <geom type="mesh" class="visual" pos="5.16948e-16 -0.0018751 -0.0539563" quat="0.477714 -0.521334 -0.477714 0.521334" mesh="humerus_adapter" material="humerus_adapter_material"/>
            <geom type="mesh" class="visual" pos="5.70724e-16 -0.0018751 -0.0539563" quat="0.477714 -0.521334 -0.477714 0.521334" mesh="joint_pin__2" material="joint_pin__2_material"/>
          </body>
        </body>
      </body>

      <!-- ===================== RIGHT FRONT FLIPPER CHAIN ===================== -->
      <body name="right_front_link_1" pos="-0.331282 -0.134454 0.0406092" quat="0.499555 0.500445 -0.499555 0.500445">
        <joint name="shoulderR1" type="hinge" axis="0 0 -1" range="-1.0 1.0"/>
        <inertial pos="0.000940071 0.0536412 -0.0437962" mass="0.245024" fullinertia="0.000128486 0.000131437 9.86795e-05 -1.004e-06 3.61792e-06 9.71519e-06"/>
        <geom type="mesh" class="visual" pos="-0.0004 0.058 -0.0595" quat="0.5 0.5 -0.5 -0.5" mesh="protector" material="protector_material"/>
        <geom type="mesh" class="collision" pos="-0.0004 0.058 -0.0595" quat="0.5 0.5 -0.5 -0.5" mesh="protector" material="protector_material"/>
        <geom type="mesh" class="visual" pos="-2.08167e-17 0.032 -0.044" quat="0.707107 -3.66291e-17 -0.707107 -3.60073e-16" mesh="fr13_s106k" material="fr13_s106k_material"/>
        <geom type="mesh" class="visual" pos="2.77556e-17 0.03 -0.0285" quat="0.707107 -1.48687e-16 0.707107 -1.51816e-16" mesh="fr13_h105k" material="fr13_h105k_material"/>
        <geom type="mesh" class="visual" pos="2.08167e-17 0.058 -0.0595" quat="0.5 -0.5 -0.5 0.5" mesh="xw540_n105_i101_stp" material="xw540_n105_i101_stp_material"/>
        <geom type="mesh" class="collision" pos="2.08167e-17 0.058 -0.0595" quat="0.5 -0.5 -0.5 0.5" mesh="xw540_n105_i101_stp" material="xw540_n105_i101_stp_material"/>
        <body name="right_front_link_2" pos="-0.0265 0.058 -0.0595" quat="0.5 0.5 0.5 0.5">
          <joint name="shoulderR2" type="hinge" range="-1.0 1.0"/>
          <inertial pos="-0.00102508 -0.0165904 -0.0243109" mass="0.224704" fullinertia="9.36859e-05 7.47238e-05 0.000114792 -3.32318e-06 -3.89075e-07 -4.1386e-07"/>
          <geom type="mesh" class="visual" pos="-1.83187e-15 -0.0155 9.71445e-17" quat="0.5 -0.5 -0.5 0.5" mesh="fr13_s106k" material="fr13_s106k_material"/>
          <geom type="mesh" class="visual" pos="-4.10783e-15 -0.031 -0.026" quat="5.07343e-14 0.707107 -5.07372e-14 0.707107" mesh="xw540_n105_i101_stp" material="xw540_n105_i101_stp_material"/>
          <geom type="mesh" class="collision" pos="-4.10783e-15 -0.031 -0.026" quat="5.07343e-14 0.707107 -5.07372e-14 0.707107" mesh="xw540_n105_i101_stp" material="xw540_n105_i101_stp_material"/>
          <geom type="mesh" class="visual" pos="0.0004 -0.031 -0.026" quat="0.5 0.5 0.5 0.5" mesh="protector" material="protector_material"/>
          <geom type="mesh" class="collision" pos="0.0004 -0.031 -0.026" quat="0.5 0.5 0.5 0.5" mesh="protector" material="protector_material"/>
          <body name="right_flipper" pos="0.0265 -0.031 -0.026" quat="0.5 -0.5 -0.5 0.5">
            <joint name="shoulderR3" type="hinge" range="-1.3 1.3"/>
            <inertial pos="-0.00507293 9.56975e-09 -0.139314" mass="0.254495" fullinertia="0.000995743 0.00108025 9.46776e-05 1.47703e-10 -4.08156e-05 -5.8036e-10"/>
            <geom type="mesh" class="visual" pos="-0.0224902 -6.52256e-16 -0.147823" quat="0.696364 -0.696364 0.122788 0.122788" mesh="flipper_silicone" material="flipper_silicone_material"/>
            <geom type="mesh" class="collision" fluidshape="ellipsoid" pos="-0.0224902 -6.52256e-16 -0.147823" quat="0.696364 -0.696364 0.122788 0.122788" mesh="flipper_silicone" material="flipper_silicone_material"/>
            <geom type="mesh" class="visual" pos="-0.0018751 -4.96131e-16 -0.0539563" quat="0.706434 -0.706434 0.0308436 0.0308436" mesh="joint_pin" material="joint_pin_material"/>
            <geom type="mesh" class="visual" pos="-0.0018751 -5.0307e-16 -0.0539563" quat="0.706434 -0.706434 0.0308436 0.0308436" mesh="joint_clamp" material="joint_clamp_material"/>
            <geom type="mesh" class="visual" pos="-0.0306545 -4.30211e-16 -0.0482414" quat="0.69934 -0.69934 0.104517 0.104517" mesh="joint_clamp" material="joint_clamp_material"/>
            <geom type="mesh" class="visual" pos="-0.0018751 -5.0307e-16 -0.0539563" quat="0.706434 -0.706434 0.0308436 0.0308436" mesh="humerus_adapter" material="humerus_adapter_material"/>
            <geom type="mesh" class="visual" pos="-0.0018751 -5.10009e-16 -0.0539563" quat="0.706434 -0.706434 0.0308436 0.0308436" mesh="joint_pin__2" material="joint_pin__2_material"/>
          </body>
        </body>
      </body>

      <!-- ===================== REAR HUB (fixed) ===================== -->
      <body name="rear_hub" pos="-0.113785 0.203934 0.0516092" quat="0.00029586 -0.707105 -0.00155534 0.707107">
        <inertial pos="0.0119856 -2.99849e-17 -0.00787955" mass="0.0203204" fullinertia="4.62588e-06 1.09516e-05 1.20876e-05 -2.73215e-24 5.95909e-08 2.10637e-24"/>
        <geom type="mesh" class="visual" pos="0.011 -2.77556e-17 -0.002" quat="0.707107 0.707107 0 3.0347e-21" mesh="fr13_h105k" material="fr13_h105k_material"/>

        <!-- ===================== LEFT REAR FLIPPER CHAIN ===================== -->
        <body name="left_rear_link_1" pos="-0.0155 -5.55112e-17 -0.032" quat="1.60079e-19 -0.707107 -0 0.707107">
          <joint name="hip_L1" type="hinge" range="-0.8 0.8"/>
          <inertial pos="0.00168914 0.0144096 -0.0253749" mass="0.224704" fullinertia="0.000114792 7.47238e-05 9.36859e-05 -4.1386e-07 3.89075e-07 3.32318e-06"/>
          <geom type="mesh" class="visual" pos="0.026 0.0155 -0.0264" quat="0.707107 -1.22868e-15 2.33147e-15 0.707107" mesh="fr13_s106k" material="fr13_s106k_material"/>
          <geom type="mesh" class="visual" pos="-6.93889e-17 -2.77556e-17 -0.0268" quat="2.32631e-15 -1 -6.60129e-16 5.47305e-16" mesh="protector" material="protector_material"/>
          <geom type="mesh" class="collision" pos="-6.93889e-17 -2.77556e-17 -0.0268" quat="2.32631e-15 -1 -6.60129e-16 5.47305e-16" mesh="protector" material="protector_material"/>
          <geom type="mesh" class="visual" pos="-1.38778e-17 -2.77556e-17 -0.0264" quat="0 1 0 0" mesh="xw540_n105_i101_stp" material="xw540_n105_i101_stp_material"/>
          <geom type="mesh" class="collision" pos="-1.38778e-17 -2.77556e-17 -0.0264" quat="0 1 0 0" mesh="xw540_n105_i101_stp" material="xw540_n105_i101_stp_material"/>
          <body name="left_rear_link_2" pos="0.0258 -1.94289e-16 -0.0264" quat="1.10167e-15 0.707107 -2.10942e-15 -0.707107">
            <joint name="hip_L2" type="hinge" range="-0.65 1.1"/>
            <inertial pos="-1.42654e-07 -0.0574016 -0.0258686" mass="0.386096" fullinertia="0.00118489 0.000138073 0.00110061 -5.43431e-09 -1.95391e-09 0.000100688"/>
            <geom type="mesh" class="visual" pos="-5.55112e-17 -0.05099 -0.0295" quat="1 -8.25855e-17 0 2.30259e-16" mesh="fr13_s105k" material="fr13_s105k_material"/>
            <geom type="mesh" class="visual" pos="-6.93889e-18 9.95644e-06 -0.0295" quat="1 -0 -1.94289e-16 4.09526e-16" mesh="xw540_n105_i101_stp" material="xw540_n105_i101_stp_material"/>
            <geom type="mesh" class="collision" pos="-6.93889e-18 9.95644e-06 -0.0295" quat="1 -0 -1.94289e-16 4.09526e-16" mesh="xw540_n105_i101_stp" material="xw540_n105_i101_stp_material"/>
            <geom type="mesh" class="visual" pos="2.08167e-17 9.95644e-06 -0.0291" quat="0.707107 -4.35436e-17 1.11022e-16 0.707107" mesh="protector" material="protector_material"/>
            <geom type="mesh" class="collision" pos="2.08167e-17 9.95644e-06 -0.0291" quat="0.707107 -4.35436e-17 1.11022e-16 0.707107" mesh="protector" material="protector_material"/>
            <geom type="mesh" class="visual" pos="-4.16334e-17 -0.0760687 -0.0329184" quat="0.663497 0.244483 -0.244483 0.663497" mesh="rear_flipper" material="rear_flipper_material"/>
            <geom type="mesh" class="collision" fluidshape="ellipsoid" pos="-4.16334e-17 -0.0760687 -0.0329184" quat="0.663497 0.244483 -0.244483 0.663497" mesh="rear_flipper" material="rear_flipper_material"/>
          </body>
        </body>
      </body>

      <!-- ===================== RIGHT REAR FLIPPER CHAIN ===================== -->
      <body name="right_rear_link_1" pos="-0.312684 0.20358 0.0671092" quat="1 -7.61795e-17 3.88578e-16 0.000890588">
        <joint name="hip_R1" type="hinge" range="-0.8 0.8"/>
        <inertial pos="-0.00168914 0.0144096 -0.0249749" mass="0.224704" fullinertia="0.000114792 7.47238e-05 9.36859e-05 4.1386e-07 -3.89075e-07 3.31983e-06"/>
        <geom type="mesh" class="visual" pos="0 2.77556e-17 -0.026" quat="0 1 0 0" mesh="xw540_n105_i101_stp" material="xw540_n105_i101_stp_material"/>
          <geom type="mesh" class="collision" pos="0 2.77556e-17 -0.026" quat="0 1 0 0" mesh="xw540_n105_i101_stp" material="xw540_n105_i101_stp_material"/>
        <geom type="mesh" class="visual" pos="0 2.77556e-17 -0.0264" quat="7.16082e-17 1 -2.54451e-16 1.55845e-16" mesh="protector" material="protector_material"/>
        <geom type="mesh" class="collision" pos="0 2.77556e-17 -0.0264" quat="7.16082e-17 1 -2.54451e-16 1.55845e-16" mesh="protector" material="protector_material"/>
        <geom type="mesh" class="visual" pos="-0.026 0.0155 -0.026" quat="6.93354e-17 0.707107 0.707107 1.51062e-16" mesh="fr13_s106k" material="fr13_s106k_material"/>
        <body name="right_rear_link_2" pos="-0.0258 1.66533e-16 -0.026" quat="0.707107 -2.76509e-16 -0.707107 -5.39823e-16">
          <joint name="hip_R2" type="hinge" range="-0.65 1.1"/>
          <inertial pos="-1.42654e-07 0.0574116 0.0228686" mass="0.386096" fullinertia="0.00118489 0.000138073 0.00110061 5.43431e-09 1.95391e-09 0.000100688"/>
          <geom type="mesh" class="visual" pos="0 0 0.0265" quat="0 1 0 0" mesh="xw540_n105_i101_stp" material="xw540_n105_i101_stp_material"/>
          <geom type="mesh" class="collision" pos="0 0 0.0265" quat="0 1 0 0" mesh="xw540_n105_i101_stp" material="xw540_n105_i101_stp_material"/>
          <geom type="mesh" class="visual" pos="0 2.77556e-17 0.0261" quat="3.72151e-17 2.78081e-17 -1 -1.4173e-16" mesh="protector" material="protector_material"/>
          <geom type="mesh" class="collision" pos="0 2.77556e-17 0.0261" quat="3.72151e-17 2.78081e-17 -1 -1.4173e-16" mesh="protector" material="protector_material"/>
          <geom type="mesh" class="visual" pos="-5.55112e-17 0.0760786 0.0299184" quat="0.244483 -0.663497 0.663497 0.244483" mesh="rear_flipper" material="rear_flipper_material"/>
          <geom type="mesh" class="collision" fluidshape="ellipsoid" pos="-5.55112e-17 0.0760786 0.0299184" quat="0.244483 -0.663497 0.663497 0.244483" mesh="rear_flipper" material="rear_flipper_material"/>
          <geom type="mesh" class="visual" pos="-5.55112e-17 0.051 0.0265" quat="2.91477e-16 1 -7.52664e-17 4.02093e-16" mesh="fr13_s105k" material="fr13_s105k_material"/>
        </body>
      </body>

    </body>
  </worldbody>

  <asset>
    <mesh file="joint_clamp.stl"/>
    <mesh file="shell__2.stl"/>
    <mesh file="joint_pin.stl"/>
    <mesh file="head_bottom.stl"/>
    <mesh file="shell_bottom_bm.stl"/>
    <mesh file="fr13_s106k.stl"/>
    <mesh file="protector.stl"/>
    <mesh file="wte4_m_clamp.stl"/>
    <mesh file="shell_bottom_br.stl"/>
    <mesh file="rear_flipper.stl"/>
    <mesh file="explorehd_2_0_public_step_1_solid1.stl"/>
    <mesh file="wte4_end_cap_10xm10_r2.stl"/>
    <mesh file="shell.stl"/>
    <mesh file="shell__3.stl"/>
    <mesh file="head_top.stl"/>
    <mesh file="fr13_s105k.stl"/>
    <mesh file="4in_flange.stl"/>
    <mesh file="fr13_h105k.stl"/>
    <mesh file="flipper_silicone.stl"/>
    <mesh file="shell_bottom_bl.stl"/>
    <mesh file="4in_tube.stl"/>
    <mesh file="shell__4.stl"/>
    <mesh file="humerus_adapter.stl"/>
    <mesh file="shell_bottom_fm.stl"/>
    <mesh file="joint_pin__2.stl"/>
    <mesh file="shell_bottom_fl.stl"/>
    <mesh file="xw540_n105_i101_stp.stl"/>
    <mesh file="shell_bottom_fr.stl"/>
    <material name="shell_bottom_bl_material" rgba="0.25098 0.25098 0.25098 1"/>
    <material name="shell_material" rgba="0.25098 0.25098 0.25098 1"/>
    <material name="protector_material" rgba="0.647059 0.647059 0.647059 1"/>
    <material name="4in_tube_material" rgba="0.796078 0.823529 0.937255 1"/>
    <material name="shell__2_material" rgba="0.25098 0.25098 0.25098 1"/>
    <material name="shell_bottom_br_material" rgba="0.25098 0.25098 0.25098 1"/>
    <material name="shell_bottom_fl_material" rgba="0.25098 0.25098 0.25098 1"/>
    <material name="explorehd_2_0_public_step_1_solid1_material" rgba="0.796078 0.823529 0.937255 1"/>
    <material name="shell_bottom_bm_material" rgba="0.25098 0.25098 0.25098 1"/>
    <material name="fr13_s105k_material" rgba="0 0 0 1"/>
    <material name="wte4_m_clamp_material" rgba="0 0 0 1"/>
    <material name="4in_flange_material" rgba="0.615686 0.811765 0.929412 1"/>
    <material name="head_bottom_material" rgba="0.25098 0.25098 0.25098 1"/>
    <material name="shell__3_material" rgba="0.25098 0.25098 0.25098 1"/>
    <material name="xw540_n105_i101_stp_material" rgba="0.301961 0.301961 0.301961 1"/>
    <material name="shell_bottom_fm_material" rgba="0.25098 0.25098 0.25098 1"/>
    <material name="fr13_h105k_material" rgba="0 0 0 1"/>
    <material name="head_top_material" rgba="0.25098 0.25098 0.25098 1"/>
    <material name="wte4_end_cap_10xm10_r2_material" rgba="0 0 0 1"/>
    <material name="shell__4_material" rgba="0.25098 0.25098 0.25098 1"/>
    <material name="shell_bottom_fr_material" rgba="0.25098 0.25098 0.25098 1"/>
    <material name="fr13_s106k_material" rgba="0 0 0 1"/>
    <material name="flipper_silicone_material" rgba="0.917647 0.917647 0.917647 1"/>
    <material name="joint_pin_material" rgba="0.25098 0.25098 0.25098 1"/>
    <material name="joint_clamp_material" rgba="0.25098 0.25098 0.25098 1"/>
    <material name="humerus_adapter_material" rgba="0.25098 0.25098 0.25098 1"/>
    <material name="joint_pin__2_material" rgba="0.25098 0.25098 0.25098 1"/>
    <material name="rear_flipper_material" rgba="0.917647 0.917647 0.917647 1"/>
  </asset>
</mujoco>
